<?xml version="1.0" encoding="utf-8"?>
<!-- This URDF was automatically created by SolidWorks to URDF Exporter! Originally created by Stephen Brawner (brawner@gmail.com) 
     Commit Version: 1.6.0-1-g15f4949  Build Version: 1.6.7594.29634000
     For more information, please see http://wiki.ros.org/sw_urdf_exporter -->
<robot
  name="my_robot">
  <link
    name="base_link">
    <inertial>
      <origin
        xyz="0.0587853718852618 1.03726776096917E-15 -0.0930559935631688"
        rpy="0 0 0" />
      <!-- <mass
        value="3.12236517080468" />
      <inertia
        ixx="0.121295108305808"
        ixz="0.0195662603783679"
        ixy="-1.2591E-15"
        izz="0.374823982635833"
        iyz="4.6146E-16"
        iyy="0.303669234388361" /> -->
        <mass
        value="33.455" />
      <inertia
        ixx="0.6022"
        ixz="-0.1197"
        ixy="-0.02364"
        izz="2.0296"
        iyz="-0.001544"
        iyy="1.7386" />
    </inertial>
    <visual>
      <origin
        xyz="0 0 0"
        rpy="0 0 0" />
      <geometry>
        <mesh
          filename="package://my_robot/meshes/base_link.STL" />
      </geometry>
      <material
        name="">
        <color
          rgba="0.6 0.6 0.6 1" />
      </material>
    </visual>
    <collision>
      <origin
        xyz="0 0 0"
        rpy="0 0 0" />
      <geometry>
        <mesh
          filename="package://my_robot/meshes/base_link.STL" />
      </geometry>
    </collision>
  </link>
  <link
    name="left_front_wheel">
    <inertial>
      <origin
        xyz="5.13930929757489E-09 -3.04509164550382E-08 -0.0552248163410726"
        rpy="0 0 0" />
      <mass
        value="8.23195517435844" />
      <inertia
        ixx="0.0630064366723534"
        ixy="-1.07299508427666E-08"
        ixz="-2.54046412544519E-09"
        iyy="0.0630064355833204"
        iyz="-1.2711075666515E-08"
        izz="0.108767039452199" />
        <!-- <mass
        value="2.637" />
      <inertia
        ixx="0.0.02018"
        ixy="0"
        ixz="0"
        iyy="0.02018"
        iyz="0"
        izz="0.03484" /> -->
    </inertial>
    <visual>
      <origin
        xyz="0 0 0"
        rpy="0 0 0" />
      <geometry>
        <mesh
          filename="package://my_robot/meshes/left_front_wheel.STL" />
      </geometry>
      <material
        name="">
        <color
          rgba="0.298039215686275 0.298039215686275 0.298039215686275 1" />
      </material>
    </visual>
    <collision>
      <origin
        xyz="0 0 0"
        rpy="0 0 0" />
      <geometry>
        <cylinder length="0.1143" radius="0.165"/>
      </geometry>
    </collision>
  </link>
  <joint
    name="left_front_wheel_joint"
    type="continuous">
    <origin
      xyz="0.256 0.22035 -0.1953"
      rpy="-1.5708 1.2311 -3.1416" />
    <parent
      link="base_link" />
    <child
      link="left_front_wheel" />
    <axis
      xyz="0 0 -1" />
    <!-- <dynamics damping="1" friction="1"/>
    <limit effort="30" velocity="1.0"/> -->
  </joint>
  <link
    name="left_rear_wheel">
    <inertial>
      <origin
        xyz="5.13930895063019E-09 -3.04509163440159E-08 -0.0552248163410726"
        rpy="0 0 0" />
      <mass
        value="8.23195517435845" />
      <inertia
        ixx="0.0630064366723535"
        ixy="-1.07299508392972E-08"
        ixz="-2.54046391580306E-09"
        iyy="0.0630064355833206"
        iyz="-1.27110757684258E-08"
        izz="0.108767039452199" />
        <!-- <mass
        value="2.637" />
      <inertia
        ixx="0.0.02018"
        ixy="0"
        ixz="0"
        iyy="0.02018"
        iyz="0"
        izz="0.03484" /> -->
    </inertial>
    <visual>
      <origin
        xyz="0 0 0"

        rpy="0 0 0" />
      <geometry>
        <mesh
          filename="package://my_robot/meshes/left_rear_wheel.STL" />
      </geometry>
      <material
        name="">
        <color
          rgba="0.298039215686275 0.298039215686275 0.298039215686275 1" />
      </material>
    </visual>
    <collision>
      <origin
        xyz="0 0 0"
        rpy="0 0 0" />
      <geometry>
        <cylinder length="0.1143" radius="0.165"/>
      </geometry>
    </collision>
  </link>
  <joint
    name="left_rear_wheel_joint"
    type="continuous">
    <origin
      xyz="-0.256 0.22035 -0.1953"
      rpy="-1.5708 -0.33051 3.1416" />
    <parent
      link="base_link" />
    <child
      link="left_rear_wheel" />
    <axis
      xyz="0 0 -1" />
    <!-- <dynamics damping="1" friction="1"/>
    <limit effort="30" velocity="1.0"/> -->
  </joint>
  <link
    name="right_rear_wheel">
    <inertial>
      <origin
        xyz="8.15809958476521E-09 -2.57078605625516E-09 -0.0552248254929292"
        rpy="0 0 0" />
      <mass
        value="8.23195748178054" />
      <inertia
        ixx="0.063006463055454"
        ixy="-1.12729348269308E-08"
        ixz="-1.17763979744703E-09"
        iyy="0.0630064519403229"
        iyz="-4.45415611022009E-09"
        izz="0.108767077064945" />
        <!-- <mass
        value="2.637" />
      <inertia
        ixx="0.0.02018"
        ixy="0"
        ixz="0"
        iyy="0.02018"
        iyz="0"
        izz="0.03484" /> -->
    </inertial>
    <visual>
      <origin
        xyz="0 0 0"
        rpy="0 0 0" />
      <geometry>
        <mesh
          filename="package://my_robot/meshes/right_rear_wheel.STL" />
      </geometry>
      <material
        name="">
        <color
          rgba="0.298039215686275 0.298039215686275 0.298039215686275 1" />
      </material>
    </visual>
    <collision>
      <origin
        xyz="0 0 0"
        rpy="0 0 0" />
      <geometry>
        <cylinder length="0.1143" radius="0.165"/>
      </geometry>
    </collision>
  </link>
  <joint
    name="right_rear_wheel_joint"
    type="continuous">
    <origin
      xyz="-0.256 -0.22035 -0.1953"
      rpy="1.5708 1.2718 -3.1416" />
    <parent
      link="base_link" />
    <child
      link="right_rear_wheel" />
    <axis
      xyz="0 0 1" />
    <!-- <dynamics damping="1" friction="1"/>
    <limit effort="30" velocity="1.0"/> -->
  </joint>
  <link
    name="right_front_wheel">
    <inertial>
      <origin
        xyz="-5.98366356463487E-11 -2.31314772891622E-08 0.0590751828145294"
        rpy="0 0 0" />
      <mass
        value="8.2319551743634" />
      <inertia
        ixx="0.0630064451523927"
        ixy="-1.43715566647794E-08"
        ixz="-3.04950039790996E-09"
        iyy="0.0630064261207298"
        iyz="-1.0117224101023E-08"
        izz="0.10876703761934" />
        <!-- <mass
        value="2.637" />
      <inertia
        ixx="0.0.02018"
        ixy="0"
        ixz="0"
        iyy="0.02018"
        iyz="0"
        izz="0.03484" /> -->
    </inertial>
    <visual>
      <origin
        xyz="0 0 0"
        rpy="0 0 0" />
      <geometry>
        <mesh
          filename="package://my_robot/meshes/right_front_wheel.STL" />
      </geometry>
      <material
        name="">
        <color
          rgba="0.298039215686275 0.298039215686275 0.298039215686275 1" />
      </material>
    </visual>
    <collision>
      <origin
        xyz="0 0 0"
        rpy="0 0 0" />
      <geometry>
        <cylinder length="0.1143" radius="0.165"/>
      </geometry>
    </collision>
  </link>
  <joint
    name="right_front_wheel_joint"
    type="continuous">
    <origin
      xyz="0.256 -0.33465 -0.1953"
      rpy="1.5708 -1.4489 3.1416" />
    <parent
      link="base_link" />
    <child
      link="right_front_wheel" />
    <axis
      xyz="0 0 1" />
    <!-- <dynamics damping="1" friction="1"/>
    <limit effort="30" velocity="1.0"/> -->
  </joint>

  <link
    name="world_link">
  </link>
  <joint
    name="base_link_world_joint"
    type="fixed">
    <origin
      xyz="0 0 -0.3603"
      rpy="0 0 0" />
    <parent
      link="base_link" />
    <child
      link="world_link" />
  </joint>
  
  <link name="sensor_laser">
    <inertial>
      <origin
        xyz="0 0 0"
        rpy="0 0 0" />
      <mass
        value="0.1" />
      <inertia
        ixx="0.000145833"
        ixy="0"
        ixz="0"
        iyy="0.000145833"
        iyz="0"
        izz="0.000125" />
    </inertial>
    

    <visual>
      <origin xyz="0 0 0" rpy="0 0 0" />
      <geometry>
      <cylinder radius="0.05" length="0.1"/>
      </geometry>
      <material
      name="">
      <color
        rgba="0.298039215686275 0.298039215686275 0.298039215686275 1" />
      </material>
    </visual>

    <collision>
        <origin xyz="0 0 0" rpy="0 0 0"/>
        <geometry>
        <cylinder radius="0.05" length="0.1"/>
        </geometry>
    </collision>
  </link>

  <joint name="joint_sensor_laser" type="fixed">
    <origin xyz="0.15 0 0.05" rpy="0 0 0"/>
    <parent link="base_link"/>
    <child link="sensor_laser"/>
  </joint>
  


  <gazebo>
    <plugin name="skid_steer_drive_controller" filename="libgazebo_ros_skid_steer_drive.so">
          <updateRate>100.0</updateRate>
          <robotNamespace>/</robotNamespace>   
          <leftFrontJoint>left_front_wheel_joint</leftFrontJoint>
          <rightFrontJoint>right_front_wheel_joint</rightFrontJoint>
          <leftRearJoint>left_rear_wheel_joint</leftRearJoint>
          <rightRearJoint>right_rear_wheel_joint</rightRearJoint>
          <wheelSeparation>0.555</wheelSeparation>
          <wheelDiameter>0.330</wheelDiameter> 
          <robotBaseFrame>base_link</robotBaseFrame>  
          <torque>50</torque>
          <topicName>/cmd_vel</topicName>
          <broadcastTF>true</broadcastTF>
          <commandTopic>/cmd_vel</commandTopic>
          <odometryTopic>/odom</odometryTopic>
          <odometryFrame>/odom</odometryFrame>
          <covariance_x>0.0001</covariance_x>
          <covariance_y>0.0001</covariance_y>
          <covariance_yaw>0.0001</covariance_yaw>
    </plugin>
  </gazebo>


  <transmission name="right_front_wheel_trans">
    <type>transmission_interface/SimpleTransmission</type>
    <joint name="right_front_wheel_joint">
      <hardwareInterface>hardware_interface/VelocityJointInterface</hardwareInterface>
    </joint>
    <actuator name="right_front_wheel_motor">
      <mechanicalReduction>1</mechanicalReduction>
      <hardwareInterface>VelocityJointInterface</hardwareInterface>
    </actuator>
  </transmission>

  <transmission name="right_rear_wheel_trans">
    <type>transmission_interface/SimpleTransmission</type>
    <joint name="right_rear_wheel_joint">
      <hardwareInterface>hardware_interface/VelocityJointInterface</hardwareInterface>
    </joint>
    <actuator name="right_rear_wheel_motor">
      <mechanicalReduction>1</mechanicalReduction>
      <hardwareInterface>VelocityJointInterface</hardwareInterface>
    </actuator>
  </transmission>

  <transmission name="left_rear_wheel_trans">
    <type>transmission_interface/SimpleTransmission</type>
    <joint name="left_rear_wheel_joint">
      <hardwareInterface>hardware_interface/VelocityJointInterface</hardwareInterface>
    </joint>
    <actuator name="left_rear_wheel_motor">
      <mechanicalReduction>1</mechanicalReduction>
      <hardwareInterface>VelocityJointInterface</hardwareInterface>
    </actuator>
  </transmission>

  <transmission name="left_front_wheel_trans">
    <type>transmission_interface/SimpleTransmission</type>
    <joint name="left_front_wheel_joint">
      <hardwareInterface>hardware_interface/VelocityJointInterface</hardwareInterface>
    </joint>
    <actuator name="left_front_wheel_motor">
      <mechanicalReduction>1</mechanicalReduction>
      <hardwareInterface>VelocityJointInterface</hardwareInterface>
    </actuator>
  </transmission>

  <!-- <gazebo>
    <plugin name="gazebo_ros_control" filename="libgazebo_ros_control.so">
      <robotNamespace>my_robot</robotNamespace>
    </plugin>
  </gazebo> -->

  <!-- <gazebo reference="sensor_laser">
    <sensor type="ray" name="head_hokuyo_sensor">
      <pose>0 0 0 0 0 0</pose>
      <visualize>false</visualize>
      <update_rate>20</update_rate>
      <ray>
        <scan>
          <horizontal>
            <samples>720</samples>
            <resolution>1</resolution>
            <min_angle>-1.570796</min_angle>
            <max_angle>1.570796</max_angle>
          </horizontal>
        </scan>
        <range>
          <min>0.10</min>
          <max>10.0</max>
          <resolution>0.01</resolution>
        </range>
        <noise>
          <type>gaussian</type>
          <mean>0.0</mean>
          <stddev>0.01</stddev>
        </noise>
      </ray>
      <plugin name="gazebo_ros_head_hokuyo_controller" filename="libgazebo_ros_laser.so">
        <topicName>/my_robot/laser/scan</topicName>
        <frameName>sensor_laser</frameName>
      </plugin>
    </sensor>
  </gazebo> -->

  
  <gazebo reference="sensor_laser">
    <sensor type="ray" name="head_hokuyo_sensor">
      <pose>0 0 0 0 0 0</pose>
      <visualize>false</visualize>
      <update_rate>40</update_rate>
      <ray>
        <scan>
          <horizontal>
            <samples>720</samples>
            <resolution>1</resolution>
            <min_angle>-1.570796</min_angle>
            <max_angle>1.570796</max_angle>
          </horizontal>
        </scan>
        <range>
          <min>0.10</min>
          <max>30.0</max>
          <resolution>0.01</resolution>
        </range>
        <noise>
          <type>gaussian</type>
          <mean>0.0</mean>
          <stddev>0.01</stddev>
        </noise>
      </ray>
      <plugin name="gazebo_ros_head_hokuyo_controller" filename="libgazebo_ros_laser.so">
        <topicName>/my_robot/laser/scan</topicName>
        <frameName>sensor_laser</frameName>
      </plugin>
    </sensor>
  </gazebo>

</robot>

